[2022-06-14 10:43:44,095] [log.py|__console] [line:43] ERROR   : Traceback (most recent call last):
  File "D:\PycharmProjects\AutoTest_platform\utils\tokenUtil.py", line 52, in wrapper
    user = s.loads(token)
  File "D:\PycharmProjects\AutoTest_platform\lib\site-packages\itsdangerous\jws.py", line 187, in loads
    self, s, salt, return_header=True
  File "D:\PycharmProjects\AutoTest_platform\lib\site-packages\itsdangerous\jws.py", line 143, in loads
    self.make_signer(salt, self.algorithm).unsign(want_bytes(s)),
  File "D:\PycharmProjects\AutoTest_platform\lib\site-packages\itsdangerous\signer.py", line 169, in unsign
    raise BadSignature("Signature %r does not match" % sig, payload=value)
itsdangerous.exc.BadSignature: Signature b'Z9Jch62tspfJfP1HnsA8oXp1kUkoTECe7tyJEgJlPrl9lXVaw30-pTdjwKeDkIl4848GHPp-bXo9hJV4BZojTA' does not match

[2022-06-14 16:40:03,727] [log.py|__console] [line:43] ERROR   : Traceback (most recent call last):
  File "D:\PycharmProjects\AutoTest_platform\lib\site-packages\flask\app.py", line 1950, in full_dispatch_request
    rv = self.dispatch_request()
  File "D:\PycharmProjects\AutoTest_platform\lib\site-packages\flask\app.py", line 1936, in dispatch_request
    return self.view_functions[rule.endpoint](**req.view_args)
  File "D:\PycharmProjects\AutoTest_platform\utils\tokenUtil.py", line 64, in wrapper
    return func(*args, **kw)
  File "D:\PycharmProjects\AutoTest_platform\views\apiTest\apiImportView.py", line 63, in import_api_from_swagger
    body.update(get_schema(parameter, swagger_data['definitions']))
  File "D:\PycharmProjects\AutoTest_platform\views\apiTest\apiImportView.py", line 75, in get_schema
    body_temp.update(get_schema(dic, definitions))
  File "D:\PycharmProjects\AutoTest_platform\views\apiTest\apiImportView.py", line 89, in get_schema
    body = {parameter['name']: parameter['type']}
KeyError: 'type'

[2022-06-14 16:53:54,645] [log.py|__console] [line:43] ERROR   : Traceback (most recent call last):
  File "D:\PycharmProjects\AutoTest_platform\lib\site-packages\flask\app.py", line 1950, in full_dispatch_request
    rv = self.dispatch_request()
  File "D:\PycharmProjects\AutoTest_platform\lib\site-packages\flask\app.py", line 1936, in dispatch_request
    return self.view_functions[rule.endpoint](**req.view_args)
  File "D:\PycharmProjects\AutoTest_platform\utils\tokenUtil.py", line 64, in wrapper
    return func(*args, **kw)
  File "D:\PycharmProjects\AutoTest_platform\views\apiTest\apiImportView.py", line 63, in import_api_from_swagger
    body.update(elem[0] for elem in get_schema(parameter, swagger_data['definitions']).values())
  File "D:\PycharmProjects\AutoTest_platform\views\apiTest\apiImportView.py", line 63, in <genexpr>
    body.update(elem[0] for elem in get_schema(parameter, swagger_data['definitions']).values())
KeyError: 0

[2022-06-14 16:56:36,975] [log.py|__console] [line:43] ERROR   : Traceback (most recent call last):
  File "D:\PycharmProjects\AutoTest_platform\lib\site-packages\flask\app.py", line 1950, in full_dispatch_request
    rv = self.dispatch_request()
  File "D:\PycharmProjects\AutoTest_platform\lib\site-packages\flask\app.py", line 1936, in dispatch_request
    return self.view_functions[rule.endpoint](**req.view_args)
  File "D:\PycharmProjects\AutoTest_platform\utils\tokenUtil.py", line 64, in wrapper
    return func(*args, **kw)
  File "D:\PycharmProjects\AutoTest_platform\views\apiTest\apiImportView.py", line 63, in import_api_from_swagger
    body.update(list(get_schema(parameter, swagger_data['definitions']).values())[0])
  File "D:\PycharmProjects\AutoTest_platform\views\apiTest\apiImportView.py", line 70, in get_schema
    schema = parameter['schema']['$ref'].split('#/definitions/')[1]
KeyError: '$ref'

[2022-06-14 17:01:18,552] [log.py|__console] [line:43] ERROR   : '$ref'
[2022-06-14 17:06:07,054] [log.py|__console] [line:43] ERROR   : dictionary update sequence element #0 has length 1; 2 is required
[2022-06-14 17:08:00,055] [log.py|__console] [line:43] ERROR   : dictionary update sequence element #0 has length 1; 2 is required
[2022-06-14 17:09:21,123] [log.py|__console] [line:43] ERROR   : dictionary update sequence element #0 has length 1; 2 is required
[2022-06-14 17:10:09,322] [log.py|__console] [line:43] ERROR   : dictionary update sequence element #0 has length 1; 2 is required
[2022-06-14 17:13:18,077] [log.py|__console] [line:43] ERROR   : eval() arg 1 must be a string, bytes or code object
[2022-06-14 17:16:14,320] [log.py|__console] [line:43] ERROR   : dictionary update sequence element #0 has length 1; 2 is required
[2022-06-14 17:20:06,464] [log.py|__console] [line:43] ERROR   : '$ref'
[2022-06-14 17:21:18,369] [log.py|__console] [line:43] ERROR   : '$ref'
[2022-06-14 17:33:19,881] [log.py|__console] [line:43] ERROR   : dictionary update sequence element #0 has length 1; 2 is required
