[2022-06-29 11:41:34,278] [log.py|__console] [line:43] ERROR   : Traceback (most recent call last):
  File "D:\PycharmProjects\AutoTest_platform\lib\site-packages\flask\app.py", line 1950, in full_dispatch_request
    rv = self.dispatch_request()
  File "D:\PycharmProjects\AutoTest_platform\lib\site-packages\flask\app.py", line 1936, in dispatch_request
    return self.view_functions[rule.endpoint](**req.view_args)
  File "D:\PycharmProjects\AutoTest_platform\utils\tokenUtil.py", line 64, in wrapper
    return func(*args, **kw)
  File "D:\PycharmProjects\AutoTest_platform\views\submittedTests\submittedTestsReportView.py", line 84, in smokeTesting_fail_reason_analysis_report
    return Response(json.dumps(output), mimetype='application/json')
  File "D:\ProgramFiles(x86)\python37\lib\json\__init__.py", line 231, in dumps
    return _default_encoder.encode(obj)
  File "D:\ProgramFiles(x86)\python37\lib\json\encoder.py", line 199, in encode
    chunks = self.iterencode(o, _one_shot=True)
  File "D:\ProgramFiles(x86)\python37\lib\json\encoder.py", line 257, in iterencode
    return _iterencode(o, 0)
  File "D:\ProgramFiles(x86)\python37\lib\json\encoder.py", line 179, in default
    raise TypeError(f'Object of type {o.__class__.__name__} '
TypeError: Object of type Row is not JSON serializable

[2022-06-29 11:43:36,151] [log.py|__console] [line:43] ERROR   : Traceback (most recent call last):
  File "D:\PycharmProjects\AutoTest_platform\lib\site-packages\flask\app.py", line 1950, in full_dispatch_request
    rv = self.dispatch_request()
  File "D:\PycharmProjects\AutoTest_platform\lib\site-packages\flask\app.py", line 1936, in dispatch_request
    return self.view_functions[rule.endpoint](**req.view_args)
  File "D:\PycharmProjects\AutoTest_platform\utils\tokenUtil.py", line 64, in wrapper
    return func(*args, **kw)
  File "D:\PycharmProjects\AutoTest_platform\views\submittedTests\submittedTestsReportView.py", line 84, in smokeTesting_fail_reason_analysis_report
    return Response(json.dumps(output), mimetype='application/json')
  File "D:\ProgramFiles(x86)\python37\lib\json\__init__.py", line 231, in dumps
    return _default_encoder.encode(obj)
  File "D:\ProgramFiles(x86)\python37\lib\json\encoder.py", line 199, in encode
    chunks = self.iterencode(o, _one_shot=True)
  File "D:\ProgramFiles(x86)\python37\lib\json\encoder.py", line 257, in iterencode
    return _iterencode(o, 0)
  File "D:\ProgramFiles(x86)\python37\lib\json\encoder.py", line 179, in default
    raise TypeError(f'Object of type {o.__class__.__name__} '
TypeError: Object of type Decimal is not JSON serializable

[2022-06-29 11:45:53,647] [log.py|__console] [line:43] ERROR   : Traceback (most recent call last):
  File "D:\PycharmProjects\AutoTest_platform\lib\site-packages\flask\app.py", line 1950, in full_dispatch_request
    rv = self.dispatch_request()
  File "D:\PycharmProjects\AutoTest_platform\lib\site-packages\flask\app.py", line 1936, in dispatch_request
    return self.view_functions[rule.endpoint](**req.view_args)
  File "D:\PycharmProjects\AutoTest_platform\utils\tokenUtil.py", line 64, in wrapper
    return func(*args, **kw)
  File "D:\PycharmProjects\AutoTest_platform\views\submittedTests\submittedTestsReportView.py", line 84, in smokeTesting_fail_reason_analysis_report
    return Response(json.dumps(output), mimetype='application/json')
  File "D:\ProgramFiles(x86)\python37\lib\json\__init__.py", line 231, in dumps
    return _default_encoder.encode(obj)
  File "D:\ProgramFiles(x86)\python37\lib\json\encoder.py", line 199, in encode
    chunks = self.iterencode(o, _one_shot=True)
  File "D:\ProgramFiles(x86)\python37\lib\json\encoder.py", line 257, in iterencode
    return _iterencode(o, 0)
  File "D:\ProgramFiles(x86)\python37\lib\json\encoder.py", line 179, in default
    raise TypeError(f'Object of type {o.__class__.__name__} '
TypeError: Object of type Decimal is not JSON serializable

[2022-06-29 15:59:44,279] [log.py|__console] [line:43] ERROR   : Traceback (most recent call last):
  File "D:\PycharmProjects\AutoTest_platform\lib\site-packages\sqlalchemy\engine\base.py", line 1707, in _execute_context
    cursor, statement, parameters, context
  File "D:\PycharmProjects\AutoTest_platform\lib\site-packages\sqlalchemy\engine\default.py", line 716, in do_execute
    cursor.execute(statement, parameters)
  File "D:\PycharmProjects\AutoTest_platform\lib\site-packages\pymysql\cursors.py", line 148, in execute
    result = self._query(query)
  File "D:\PycharmProjects\AutoTest_platform\lib\site-packages\pymysql\cursors.py", line 310, in _query
    conn.query(q)
  File "D:\PycharmProjects\AutoTest_platform\lib\site-packages\pymysql\connections.py", line 548, in query
    self._affected_rows = self._read_query_result(unbuffered=unbuffered)
  File "D:\PycharmProjects\AutoTest_platform\lib\site-packages\pymysql\connections.py", line 775, in _read_query_result
    result.read()
  File "D:\PycharmProjects\AutoTest_platform\lib\site-packages\pymysql\connections.py", line 1156, in read
    first_packet = self.connection._read_packet()
  File "D:\PycharmProjects\AutoTest_platform\lib\site-packages\pymysql\connections.py", line 725, in _read_packet
    packet.raise_for_error()
  File "D:\PycharmProjects\AutoTest_platform\lib\site-packages\pymysql\protocol.py", line 221, in raise_for_error
    err.raise_mysql_exception(self._data)
  File "D:\PycharmProjects\AutoTest_platform\lib\site-packages\pymysql\err.py", line 143, in raise_mysql_exception
    raise errorclass(errno, errval)
pymysql.err.OperationalError: (1054, "Unknown column 'submitted_tests.submitted_test_director_id' in 'field list'")

The above exception was the direct cause of the following exception:

Traceback (most recent call last):
  File "D:\PycharmProjects\AutoTest_platform\lib\site-packages\flask\app.py", line 1950, in full_dispatch_request
    rv = self.dispatch_request()
  File "D:\PycharmProjects\AutoTest_platform\lib\site-packages\flask\app.py", line 1936, in dispatch_request
    return self.view_functions[rule.endpoint](**req.view_args)
  File "D:\PycharmProjects\AutoTest_platform\utils\tokenUtil.py", line 64, in wrapper
    return func(*args, **kw)
  File "D:\PycharmProjects\AutoTest_platform\views\submittedTests\submittedTestsManagementView.py", line 63, in list_submittedTests
    submittedTests = SubmittedTests.query.filter(*filterList).order_by(SubmittedTests.id.desc()).paginate(int(param_currentPage), int(param_pageSize)).items
  File "D:\PycharmProjects\AutoTest_platform\lib\site-packages\flask_sqlalchemy\__init__.py", line 534, in paginate
    items = self.limit(per_page).offset((page - 1) * per_page).all()
  File "D:\PycharmProjects\AutoTest_platform\lib\site-packages\sqlalchemy\orm\query.py", line 2699, in all
    return self._iter().all()
  File "D:\PycharmProjects\AutoTest_platform\lib\site-packages\sqlalchemy\orm\query.py", line 2837, in _iter
    execution_options={"_sa_orm_load_options": self.load_options},
  File "D:\PycharmProjects\AutoTest_platform\lib\site-packages\sqlalchemy\orm\session.py", line 1670, in execute
    result = conn._execute_20(statement, params or {}, execution_options)
  File "D:\PycharmProjects\AutoTest_platform\lib\site-packages\sqlalchemy\engine\base.py", line 1521, in _execute_20
    return meth(self, args_10style, kwargs_10style, execution_options)
  File "D:\PycharmProjects\AutoTest_platform\lib\site-packages\sqlalchemy\sql\elements.py", line 314, in _execute_on_connection
    self, multiparams, params, execution_options
  File "D:\PycharmProjects\AutoTest_platform\lib\site-packages\sqlalchemy\engine\base.py", line 1400, in _execute_clauseelement
    cache_hit=cache_hit,
  File "D:\PycharmProjects\AutoTest_platform\lib\site-packages\sqlalchemy\engine\base.py", line 1750, in _execute_context
    e, statement, parameters, cursor, context
  File "D:\PycharmProjects\AutoTest_platform\lib\site-packages\sqlalchemy\engine\base.py", line 1931, in _handle_dbapi_exception
    sqlalchemy_exception, with_traceback=exc_info[2], from_=e
  File "D:\PycharmProjects\AutoTest_platform\lib\site-packages\sqlalchemy\util\compat.py", line 211, in raise_
    raise exception
  File "D:\PycharmProjects\AutoTest_platform\lib\site-packages\sqlalchemy\engine\base.py", line 1707, in _execute_context
    cursor, statement, parameters, context
  File "D:\PycharmProjects\AutoTest_platform\lib\site-packages\sqlalchemy\engine\default.py", line 716, in do_execute
    cursor.execute(statement, parameters)
  File "D:\PycharmProjects\AutoTest_platform\lib\site-packages\pymysql\cursors.py", line 148, in execute
    result = self._query(query)
  File "D:\PycharmProjects\AutoTest_platform\lib\site-packages\pymysql\cursors.py", line 310, in _query
    conn.query(q)
  File "D:\PycharmProjects\AutoTest_platform\lib\site-packages\pymysql\connections.py", line 548, in query
    self._affected_rows = self._read_query_result(unbuffered=unbuffered)
  File "D:\PycharmProjects\AutoTest_platform\lib\site-packages\pymysql\connections.py", line 775, in _read_query_result
    result.read()
  File "D:\PycharmProjects\AutoTest_platform\lib\site-packages\pymysql\connections.py", line 1156, in read
    first_packet = self.connection._read_packet()
  File "D:\PycharmProjects\AutoTest_platform\lib\site-packages\pymysql\connections.py", line 725, in _read_packet
    packet.raise_for_error()
  File "D:\PycharmProjects\AutoTest_platform\lib\site-packages\pymysql\protocol.py", line 221, in raise_for_error
    err.raise_mysql_exception(self._data)
  File "D:\PycharmProjects\AutoTest_platform\lib\site-packages\pymysql\err.py", line 143, in raise_mysql_exception
    raise errorclass(errno, errval)
sqlalchemy.exc.OperationalError: (pymysql.err.OperationalError) (1054, "Unknown column 'submitted_tests.submitted_test_director_id' in 'field list'")
[SQL: SELECT submitted_tests.id AS submitted_tests_id, submitted_tests.project_id AS submitted_tests_project_id, submitted_tests.submitted_test_name AS submitted_tests_submitted_test_name, submitted_tests.submitted_date AS submitted_tests_submitted_date, submitted_tests.test_date AS submitted_tests_test_date, submitted_tests.online_date AS submitted_tests_online_date, submitted_tests.submitted_test_director_id AS submitted_tests_submitted_test_director_id, submitted_tests.submitted_test_director AS submitted_tests_submitted_test_director, submitted_tests.fix_bug_director_id AS submitted_tests_fix_bug_director_id, submitted_tests.fix_bug_director AS submitted_tests_fix_bug_director, submitted_tests.test_director_id AS submitted_tests_test_director_id, submitted_tests.test_director AS submitted_tests_test_director, submitted_tests.self_test_report_url AS submitted_tests_self_test_report_url, submitted_tests.test_url AS submitted_tests_test_url, submitted_tests.test_scope AS submitted_tests_test_scope, submitted_tests.influence_scope AS submitted_tests_influence_scope, submitted_tests.points_for_attention AS submitted_tests_points_for_attention, submitted_tests.config_url AS submitted_tests_config_url, submitted_tests.script_url AS submitted_tests_script_url, submitted_tests.compatibility_desc AS submitted_tests_compatibility_desc, submitted_tests.file_name AS submitted_tests_file_name, submitted_tests.test_status AS submitted_tests_test_status, submitted_tests.smoke_testing_result AS submitted_tests_smoke_testing_result, submitted_tests.smoke_testing_fail_reason_category AS submitted_tests_smoke_testing_fail_reason_category, submitted_tests.smoke_testing_fail_reason_detail AS submitted_tests_smoke_testing_fail_reason_detail, submitted_tests.test_result AS submitted_tests_test_result, submitted_tests.complete_date AS submitted_tests_complete_date 
FROM submitted_tests ORDER BY submitted_tests.id DESC 
 LIMIT %(param_1)s, %(param_2)s]
[parameters: {'param_1': 0, 'param_2': 10}]
(Background on this error at: http://sqlalche.me/e/14/e3q8)

[2022-06-29 15:59:52,291] [log.py|__console] [line:43] ERROR   : Traceback (most recent call last):
  File "D:\PycharmProjects\AutoTest_platform\lib\site-packages\sqlalchemy\engine\base.py", line 1707, in _execute_context
    cursor, statement, parameters, context
  File "D:\PycharmProjects\AutoTest_platform\lib\site-packages\sqlalchemy\engine\default.py", line 716, in do_execute
    cursor.execute(statement, parameters)
  File "D:\PycharmProjects\AutoTest_platform\lib\site-packages\pymysql\cursors.py", line 148, in execute
    result = self._query(query)
  File "D:\PycharmProjects\AutoTest_platform\lib\site-packages\pymysql\cursors.py", line 310, in _query
    conn.query(q)
  File "D:\PycharmProjects\AutoTest_platform\lib\site-packages\pymysql\connections.py", line 548, in query
    self._affected_rows = self._read_query_result(unbuffered=unbuffered)
  File "D:\PycharmProjects\AutoTest_platform\lib\site-packages\pymysql\connections.py", line 775, in _read_query_result
    result.read()
  File "D:\PycharmProjects\AutoTest_platform\lib\site-packages\pymysql\connections.py", line 1156, in read
    first_packet = self.connection._read_packet()
  File "D:\PycharmProjects\AutoTest_platform\lib\site-packages\pymysql\connections.py", line 725, in _read_packet
    packet.raise_for_error()
  File "D:\PycharmProjects\AutoTest_platform\lib\site-packages\pymysql\protocol.py", line 221, in raise_for_error
    err.raise_mysql_exception(self._data)
  File "D:\PycharmProjects\AutoTest_platform\lib\site-packages\pymysql\err.py", line 143, in raise_mysql_exception
    raise errorclass(errno, errval)
pymysql.err.OperationalError: (1054, "Unknown column 'submitted_tests.submitted_test_director_id' in 'field list'")

The above exception was the direct cause of the following exception:

Traceback (most recent call last):
  File "D:\PycharmProjects\AutoTest_platform\lib\site-packages\flask\app.py", line 1950, in full_dispatch_request
    rv = self.dispatch_request()
  File "D:\PycharmProjects\AutoTest_platform\lib\site-packages\flask\app.py", line 1936, in dispatch_request
    return self.view_functions[rule.endpoint](**req.view_args)
  File "D:\PycharmProjects\AutoTest_platform\utils\tokenUtil.py", line 64, in wrapper
    return func(*args, **kw)
  File "D:\PycharmProjects\AutoTest_platform\views\submittedTests\submittedTestsManagementView.py", line 63, in list_submittedTests
    submittedTests = SubmittedTests.query.filter(*filterList).order_by(SubmittedTests.id.desc()).paginate(int(param_currentPage), int(param_pageSize)).items
  File "D:\PycharmProjects\AutoTest_platform\lib\site-packages\flask_sqlalchemy\__init__.py", line 534, in paginate
    items = self.limit(per_page).offset((page - 1) * per_page).all()
  File "D:\PycharmProjects\AutoTest_platform\lib\site-packages\sqlalchemy\orm\query.py", line 2699, in all
    return self._iter().all()
  File "D:\PycharmProjects\AutoTest_platform\lib\site-packages\sqlalchemy\orm\query.py", line 2837, in _iter
    execution_options={"_sa_orm_load_options": self.load_options},
  File "D:\PycharmProjects\AutoTest_platform\lib\site-packages\sqlalchemy\orm\session.py", line 1670, in execute
    result = conn._execute_20(statement, params or {}, execution_options)
  File "D:\PycharmProjects\AutoTest_platform\lib\site-packages\sqlalchemy\engine\base.py", line 1521, in _execute_20
    return meth(self, args_10style, kwargs_10style, execution_options)
  File "D:\PycharmProjects\AutoTest_platform\lib\site-packages\sqlalchemy\sql\elements.py", line 314, in _execute_on_connection
    self, multiparams, params, execution_options
  File "D:\PycharmProjects\AutoTest_platform\lib\site-packages\sqlalchemy\engine\base.py", line 1400, in _execute_clauseelement
    cache_hit=cache_hit,
  File "D:\PycharmProjects\AutoTest_platform\lib\site-packages\sqlalchemy\engine\base.py", line 1750, in _execute_context
    e, statement, parameters, cursor, context
  File "D:\PycharmProjects\AutoTest_platform\lib\site-packages\sqlalchemy\engine\base.py", line 1931, in _handle_dbapi_exception
    sqlalchemy_exception, with_traceback=exc_info[2], from_=e
  File "D:\PycharmProjects\AutoTest_platform\lib\site-packages\sqlalchemy\util\compat.py", line 211, in raise_
    raise exception
  File "D:\PycharmProjects\AutoTest_platform\lib\site-packages\sqlalchemy\engine\base.py", line 1707, in _execute_context
    cursor, statement, parameters, context
  File "D:\PycharmProjects\AutoTest_platform\lib\site-packages\sqlalchemy\engine\default.py", line 716, in do_execute
    cursor.execute(statement, parameters)
  File "D:\PycharmProjects\AutoTest_platform\lib\site-packages\pymysql\cursors.py", line 148, in execute
    result = self._query(query)
  File "D:\PycharmProjects\AutoTest_platform\lib\site-packages\pymysql\cursors.py", line 310, in _query
    conn.query(q)
  File "D:\PycharmProjects\AutoTest_platform\lib\site-packages\pymysql\connections.py", line 548, in query
    self._affected_rows = self._read_query_result(unbuffered=unbuffered)
  File "D:\PycharmProjects\AutoTest_platform\lib\site-packages\pymysql\connections.py", line 775, in _read_query_result
    result.read()
  File "D:\PycharmProjects\AutoTest_platform\lib\site-packages\pymysql\connections.py", line 1156, in read
    first_packet = self.connection._read_packet()
  File "D:\PycharmProjects\AutoTest_platform\lib\site-packages\pymysql\connections.py", line 725, in _read_packet
    packet.raise_for_error()
  File "D:\PycharmProjects\AutoTest_platform\lib\site-packages\pymysql\protocol.py", line 221, in raise_for_error
    err.raise_mysql_exception(self._data)
  File "D:\PycharmProjects\AutoTest_platform\lib\site-packages\pymysql\err.py", line 143, in raise_mysql_exception
    raise errorclass(errno, errval)
sqlalchemy.exc.OperationalError: (pymysql.err.OperationalError) (1054, "Unknown column 'submitted_tests.submitted_test_director_id' in 'field list'")
[SQL: SELECT submitted_tests.id AS submitted_tests_id, submitted_tests.project_id AS submitted_tests_project_id, submitted_tests.submitted_test_name AS submitted_tests_submitted_test_name, submitted_tests.submitted_date AS submitted_tests_submitted_date, submitted_tests.test_date AS submitted_tests_test_date, submitted_tests.online_date AS submitted_tests_online_date, submitted_tests.submitted_test_director_id AS submitted_tests_submitted_test_director_id, submitted_tests.submitted_test_director AS submitted_tests_submitted_test_director, submitted_tests.fix_bug_director_id AS submitted_tests_fix_bug_director_id, submitted_tests.fix_bug_director AS submitted_tests_fix_bug_director, submitted_tests.test_director_id AS submitted_tests_test_director_id, submitted_tests.test_director AS submitted_tests_test_director, submitted_tests.self_test_report_url AS submitted_tests_self_test_report_url, submitted_tests.test_url AS submitted_tests_test_url, submitted_tests.test_scope AS submitted_tests_test_scope, submitted_tests.influence_scope AS submitted_tests_influence_scope, submitted_tests.points_for_attention AS submitted_tests_points_for_attention, submitted_tests.config_url AS submitted_tests_config_url, submitted_tests.script_url AS submitted_tests_script_url, submitted_tests.compatibility_desc AS submitted_tests_compatibility_desc, submitted_tests.file_name AS submitted_tests_file_name, submitted_tests.test_status AS submitted_tests_test_status, submitted_tests.smoke_testing_result AS submitted_tests_smoke_testing_result, submitted_tests.smoke_testing_fail_reason_category AS submitted_tests_smoke_testing_fail_reason_category, submitted_tests.smoke_testing_fail_reason_detail AS submitted_tests_smoke_testing_fail_reason_detail, submitted_tests.test_result AS submitted_tests_test_result, submitted_tests.complete_date AS submitted_tests_complete_date 
FROM submitted_tests ORDER BY submitted_tests.id DESC 
 LIMIT %(param_1)s, %(param_2)s]
[parameters: {'param_1': 0, 'param_2': 10}]
(Background on this error at: http://sqlalche.me/e/14/e3q8)

[2022-06-29 16:18:50,245] [log.py|__console] [line:43] ERROR   : Traceback (most recent call last):
  File "D:\PycharmProjects\AutoTest_platform\lib\site-packages\flask\app.py", line 1950, in full_dispatch_request
    rv = self.dispatch_request()
  File "D:\PycharmProjects\AutoTest_platform\lib\site-packages\flask\app.py", line 1936, in dispatch_request
    return self.view_functions[rule.endpoint](**req.view_args)
  File "D:\PycharmProjects\AutoTest_platform\utils\tokenUtil.py", line 64, in wrapper
    return func(*args, **kw)
  File "D:\PycharmProjects\AutoTest_platform\views\base\userView.py", line 302, in get_user_options
    users = User.query.filter(User.name != 'admin').all()
AttributeError: type object 'User' has no attribute 'name'

[2022-06-29 16:19:08,722] [log.py|__console] [line:43] ERROR   : Traceback (most recent call last):
  File "D:\PycharmProjects\AutoTest_platform\lib\site-packages\flask\app.py", line 1950, in full_dispatch_request
    rv = self.dispatch_request()
  File "D:\PycharmProjects\AutoTest_platform\lib\site-packages\flask\app.py", line 1936, in dispatch_request
    return self.view_functions[rule.endpoint](**req.view_args)
  File "D:\PycharmProjects\AutoTest_platform\utils\tokenUtil.py", line 64, in wrapper
    return func(*args, **kw)
  File "D:\PycharmProjects\AutoTest_platform\views\base\userView.py", line 306, in get_user_options
    dic = {'value': user.id, 'label': user.nickname}
AttributeError: 'dict' object has no attribute 'id'

[2022-06-29 16:19:48,062] [log.py|__console] [line:43] ERROR   : Traceback (most recent call last):
  File "D:\PycharmProjects\AutoTest_platform\lib\site-packages\flask\app.py", line 1950, in full_dispatch_request
    rv = self.dispatch_request()
  File "D:\PycharmProjects\AutoTest_platform\lib\site-packages\flask\app.py", line 1936, in dispatch_request
    return self.view_functions[rule.endpoint](**req.view_args)
  File "D:\PycharmProjects\AutoTest_platform\utils\tokenUtil.py", line 64, in wrapper
    return func(*args, **kw)
  File "D:\PycharmProjects\AutoTest_platform\views\base\userView.py", line 306, in get_user_options
    dic = {'value': user.id, 'label': user.nickname}
AttributeError: 'dict' object has no attribute 'id'

[2022-06-29 16:48:45,936] [log.py|__console] [line:43] ERROR   : Traceback (most recent call last):
  File "D:\PycharmProjects\AutoTest_platform\lib\site-packages\flask\app.py", line 1950, in full_dispatch_request
    rv = self.dispatch_request()
  File "D:\PycharmProjects\AutoTest_platform\lib\site-packages\flask\app.py", line 1936, in dispatch_request
    return self.view_functions[rule.endpoint](**req.view_args)
  File "D:\PycharmProjects\AutoTest_platform\utils\tokenUtil.py", line 64, in wrapper
    return func(*args, **kw)
  File "D:\PycharmProjects\AutoTest_platform\views\submittedTests\submittedTestsManagementView.py", line 77, in list_submittedTests
    dict['fix_bug_director_id'] = ast.literal_eval(dict['fix_bug_director_id'])
  File "D:\ProgramFiles(x86)\python37\lib\ast.py", line 91, in literal_eval
    return _convert(node_or_string)
  File "D:\ProgramFiles(x86)\python37\lib\ast.py", line 90, in _convert
    return _convert_signed_num(node)
  File "D:\ProgramFiles(x86)\python37\lib\ast.py", line 63, in _convert_signed_num
    return _convert_num(node)
  File "D:\ProgramFiles(x86)\python37\lib\ast.py", line 55, in _convert_num
    raise ValueError('malformed node or string: ' + repr(node))
ValueError: malformed node or string: None

[2022-06-29 16:49:44,415] [log.py|__console] [line:43] ERROR   : Traceback (most recent call last):
  File "D:\PycharmProjects\AutoTest_platform\lib\site-packages\flask\app.py", line 1950, in full_dispatch_request
    rv = self.dispatch_request()
  File "D:\PycharmProjects\AutoTest_platform\lib\site-packages\flask\app.py", line 1936, in dispatch_request
    return self.view_functions[rule.endpoint](**req.view_args)
  File "D:\PycharmProjects\AutoTest_platform\utils\tokenUtil.py", line 64, in wrapper
    return func(*args, **kw)
  File "D:\PycharmProjects\AutoTest_platform\views\submittedTests\submittedTestsManagementView.py", line 78, in list_submittedTests
    dict['fix_bug_director_id'] = ast.literal_eval(dict['fix_bug_director_id'])
  File "D:\ProgramFiles(x86)\python37\lib\ast.py", line 91, in literal_eval
    return _convert(node_or_string)
  File "D:\ProgramFiles(x86)\python37\lib\ast.py", line 90, in _convert
    return _convert_signed_num(node)
  File "D:\ProgramFiles(x86)\python37\lib\ast.py", line 63, in _convert_signed_num
    return _convert_num(node)
  File "D:\ProgramFiles(x86)\python37\lib\ast.py", line 55, in _convert_num
    raise ValueError('malformed node or string: ' + repr(node))
ValueError: malformed node or string: None

[2022-06-29 16:57:12,944] [log.py|__console] [line:43] ERROR   : Traceback (most recent call last):
  File "D:\PycharmProjects\AutoTest_platform\lib\site-packages\sqlalchemy\engine\base.py", line 1707, in _execute_context
    cursor, statement, parameters, context
  File "D:\PycharmProjects\AutoTest_platform\lib\site-packages\sqlalchemy\engine\default.py", line 716, in do_execute
    cursor.execute(statement, parameters)
  File "D:\PycharmProjects\AutoTest_platform\lib\site-packages\pymysql\cursors.py", line 148, in execute
    result = self._query(query)
  File "D:\PycharmProjects\AutoTest_platform\lib\site-packages\pymysql\cursors.py", line 310, in _query
    conn.query(q)
  File "D:\PycharmProjects\AutoTest_platform\lib\site-packages\pymysql\connections.py", line 548, in query
    self._affected_rows = self._read_query_result(unbuffered=unbuffered)
  File "D:\PycharmProjects\AutoTest_platform\lib\site-packages\pymysql\connections.py", line 775, in _read_query_result
    result.read()
  File "D:\PycharmProjects\AutoTest_platform\lib\site-packages\pymysql\connections.py", line 1156, in read
    first_packet = self.connection._read_packet()
  File "D:\PycharmProjects\AutoTest_platform\lib\site-packages\pymysql\connections.py", line 725, in _read_packet
    packet.raise_for_error()
  File "D:\PycharmProjects\AutoTest_platform\lib\site-packages\pymysql\protocol.py", line 221, in raise_for_error
    err.raise_mysql_exception(self._data)
  File "D:\PycharmProjects\AutoTest_platform\lib\site-packages\pymysql\err.py", line 143, in raise_mysql_exception
    raise errorclass(errno, errval)
pymysql.err.OperationalError: (1241, 'Operand should contain 1 column(s)')

The above exception was the direct cause of the following exception:

Traceback (most recent call last):
  File "D:\PycharmProjects\AutoTest_platform\lib\site-packages\flask\app.py", line 1950, in full_dispatch_request
    rv = self.dispatch_request()
  File "D:\PycharmProjects\AutoTest_platform\lib\site-packages\flask\app.py", line 1936, in dispatch_request
    return self.view_functions[rule.endpoint](**req.view_args)
  File "D:\PycharmProjects\AutoTest_platform\utils\tokenUtil.py", line 64, in wrapper
    return func(*args, **kw)
  File "D:\PycharmProjects\AutoTest_platform\views\submittedTests\submittedTestsManagementView.py", line 207, in edit_submittedTest
    db.session.commit()
  File "<string>", line 2, in commit
  File "D:\PycharmProjects\AutoTest_platform\lib\site-packages\sqlalchemy\orm\session.py", line 1423, in commit
    self._transaction.commit(_to_root=self.future)
  File "D:\PycharmProjects\AutoTest_platform\lib\site-packages\sqlalchemy\orm\session.py", line 829, in commit
    self._prepare_impl()
  File "D:\PycharmProjects\AutoTest_platform\lib\site-packages\sqlalchemy\orm\session.py", line 808, in _prepare_impl
    self.session.flush()
  File "D:\PycharmProjects\AutoTest_platform\lib\site-packages\sqlalchemy\orm\session.py", line 3255, in flush
    self._flush(objects)
  File "D:\PycharmProjects\AutoTest_platform\lib\site-packages\sqlalchemy\orm\session.py", line 3395, in _flush
    transaction.rollback(_capture_exception=True)
  File "D:\PycharmProjects\AutoTest_platform\lib\site-packages\sqlalchemy\util\langhelpers.py", line 72, in __exit__
    with_traceback=exc_tb,
  File "D:\PycharmProjects\AutoTest_platform\lib\site-packages\sqlalchemy\util\compat.py", line 211, in raise_
    raise exception
  File "D:\PycharmProjects\AutoTest_platform\lib\site-packages\sqlalchemy\orm\session.py", line 3355, in _flush
    flush_context.execute()
  File "D:\PycharmProjects\AutoTest_platform\lib\site-packages\sqlalchemy\orm\unitofwork.py", line 453, in execute
    rec.execute(self)
  File "D:\PycharmProjects\AutoTest_platform\lib\site-packages\sqlalchemy\orm\unitofwork.py", line 630, in execute
    uow,
  File "D:\PycharmProjects\AutoTest_platform\lib\site-packages\sqlalchemy\orm\persistence.py", line 239, in save_obj
    update,
  File "D:\PycharmProjects\AutoTest_platform\lib\site-packages\sqlalchemy\orm\persistence.py", line 999, in _emit_update_statements
    statement, multiparams, execution_options=execution_options
  File "D:\PycharmProjects\AutoTest_platform\lib\site-packages\sqlalchemy\engine\base.py", line 1521, in _execute_20
    return meth(self, args_10style, kwargs_10style, execution_options)
  File "D:\PycharmProjects\AutoTest_platform\lib\site-packages\sqlalchemy\sql\elements.py", line 314, in _execute_on_connection
    self, multiparams, params, execution_options
  File "D:\PycharmProjects\AutoTest_platform\lib\site-packages\sqlalchemy\engine\base.py", line 1400, in _execute_clauseelement
    cache_hit=cache_hit,
  File "D:\PycharmProjects\AutoTest_platform\lib\site-packages\sqlalchemy\engine\base.py", line 1750, in _execute_context
    e, statement, parameters, cursor, context
  File "D:\PycharmProjects\AutoTest_platform\lib\site-packages\sqlalchemy\engine\base.py", line 1931, in _handle_dbapi_exception
    sqlalchemy_exception, with_traceback=exc_info[2], from_=e
  File "D:\PycharmProjects\AutoTest_platform\lib\site-packages\sqlalchemy\util\compat.py", line 211, in raise_
    raise exception
  File "D:\PycharmProjects\AutoTest_platform\lib\site-packages\sqlalchemy\engine\base.py", line 1707, in _execute_context
    cursor, statement, parameters, context
  File "D:\PycharmProjects\AutoTest_platform\lib\site-packages\sqlalchemy\engine\default.py", line 716, in do_execute
    cursor.execute(statement, parameters)
  File "D:\PycharmProjects\AutoTest_platform\lib\site-packages\pymysql\cursors.py", line 148, in execute
    result = self._query(query)
  File "D:\PycharmProjects\AutoTest_platform\lib\site-packages\pymysql\cursors.py", line 310, in _query
    conn.query(q)
  File "D:\PycharmProjects\AutoTest_platform\lib\site-packages\pymysql\connections.py", line 548, in query
    self._affected_rows = self._read_query_result(unbuffered=unbuffered)
  File "D:\PycharmProjects\AutoTest_platform\lib\site-packages\pymysql\connections.py", line 775, in _read_query_result
    result.read()
  File "D:\PycharmProjects\AutoTest_platform\lib\site-packages\pymysql\connections.py", line 1156, in read
    first_packet = self.connection._read_packet()
  File "D:\PycharmProjects\AutoTest_platform\lib\site-packages\pymysql\connections.py", line 725, in _read_packet
    packet.raise_for_error()
  File "D:\PycharmProjects\AutoTest_platform\lib\site-packages\pymysql\protocol.py", line 221, in raise_for_error
    err.raise_mysql_exception(self._data)
  File "D:\PycharmProjects\AutoTest_platform\lib\site-packages\pymysql\err.py", line 143, in raise_mysql_exception
    raise errorclass(errno, errval)
sqlalchemy.exc.OperationalError: (pymysql.err.OperationalError) (1241, 'Operand should contain 1 column(s)')
[SQL: UPDATE submitted_tests SET submitted_date=%(submitted_date)s, test_date=%(test_date)s, submitted_test_director_id=%(submitted_test_director_id)s, fix_bug_director_id=%(fix_bug_director_id)s WHERE submitted_tests.id = %(submitted_tests_id)s]
[parameters: {'submitted_date': datetime.datetime(2022, 6, 2, 0, 0), 'test_date': datetime.datetime(2022, 6, 2, 0, 0), 'submitted_test_director_id': 5, 'fix_bug_director_id': [4, 5], 'submitted_tests_id': 31}]
(Background on this error at: http://sqlalche.me/e/14/e3q8)

[2022-06-29 16:57:36,094] [log.py|__console] [line:43] ERROR   : Traceback (most recent call last):
  File "D:\PycharmProjects\AutoTest_platform\lib\site-packages\sqlalchemy\engine\base.py", line 1707, in _execute_context
    cursor, statement, parameters, context
  File "D:\PycharmProjects\AutoTest_platform\lib\site-packages\sqlalchemy\engine\default.py", line 716, in do_execute
    cursor.execute(statement, parameters)
  File "D:\PycharmProjects\AutoTest_platform\lib\site-packages\pymysql\cursors.py", line 148, in execute
    result = self._query(query)
  File "D:\PycharmProjects\AutoTest_platform\lib\site-packages\pymysql\cursors.py", line 310, in _query
    conn.query(q)
  File "D:\PycharmProjects\AutoTest_platform\lib\site-packages\pymysql\connections.py", line 548, in query
    self._affected_rows = self._read_query_result(unbuffered=unbuffered)
  File "D:\PycharmProjects\AutoTest_platform\lib\site-packages\pymysql\connections.py", line 775, in _read_query_result
    result.read()
  File "D:\PycharmProjects\AutoTest_platform\lib\site-packages\pymysql\connections.py", line 1156, in read
    first_packet = self.connection._read_packet()
  File "D:\PycharmProjects\AutoTest_platform\lib\site-packages\pymysql\connections.py", line 725, in _read_packet
    packet.raise_for_error()
  File "D:\PycharmProjects\AutoTest_platform\lib\site-packages\pymysql\protocol.py", line 221, in raise_for_error
    err.raise_mysql_exception(self._data)
  File "D:\PycharmProjects\AutoTest_platform\lib\site-packages\pymysql\err.py", line 143, in raise_mysql_exception
    raise errorclass(errno, errval)
pymysql.err.OperationalError: (1241, 'Operand should contain 1 column(s)')

The above exception was the direct cause of the following exception:

Traceback (most recent call last):
  File "D:\PycharmProjects\AutoTest_platform\lib\site-packages\flask\app.py", line 1950, in full_dispatch_request
    rv = self.dispatch_request()
  File "D:\PycharmProjects\AutoTest_platform\lib\site-packages\flask\app.py", line 1936, in dispatch_request
    return self.view_functions[rule.endpoint](**req.view_args)
  File "D:\PycharmProjects\AutoTest_platform\utils\tokenUtil.py", line 64, in wrapper
    return func(*args, **kw)
  File "D:\PycharmProjects\AutoTest_platform\views\submittedTests\submittedTestsManagementView.py", line 207, in edit_submittedTest
    db.session.commit()
  File "<string>", line 2, in commit
  File "D:\PycharmProjects\AutoTest_platform\lib\site-packages\sqlalchemy\orm\session.py", line 1423, in commit
    self._transaction.commit(_to_root=self.future)
  File "D:\PycharmProjects\AutoTest_platform\lib\site-packages\sqlalchemy\orm\session.py", line 829, in commit
    self._prepare_impl()
  File "D:\PycharmProjects\AutoTest_platform\lib\site-packages\sqlalchemy\orm\session.py", line 808, in _prepare_impl
    self.session.flush()
  File "D:\PycharmProjects\AutoTest_platform\lib\site-packages\sqlalchemy\orm\session.py", line 3255, in flush
    self._flush(objects)
  File "D:\PycharmProjects\AutoTest_platform\lib\site-packages\sqlalchemy\orm\session.py", line 3395, in _flush
    transaction.rollback(_capture_exception=True)
  File "D:\PycharmProjects\AutoTest_platform\lib\site-packages\sqlalchemy\util\langhelpers.py", line 72, in __exit__
    with_traceback=exc_tb,
  File "D:\PycharmProjects\AutoTest_platform\lib\site-packages\sqlalchemy\util\compat.py", line 211, in raise_
    raise exception
  File "D:\PycharmProjects\AutoTest_platform\lib\site-packages\sqlalchemy\orm\session.py", line 3355, in _flush
    flush_context.execute()
  File "D:\PycharmProjects\AutoTest_platform\lib\site-packages\sqlalchemy\orm\unitofwork.py", line 453, in execute
    rec.execute(self)
  File "D:\PycharmProjects\AutoTest_platform\lib\site-packages\sqlalchemy\orm\unitofwork.py", line 630, in execute
    uow,
  File "D:\PycharmProjects\AutoTest_platform\lib\site-packages\sqlalchemy\orm\persistence.py", line 239, in save_obj
    update,
  File "D:\PycharmProjects\AutoTest_platform\lib\site-packages\sqlalchemy\orm\persistence.py", line 999, in _emit_update_statements
    statement, multiparams, execution_options=execution_options
  File "D:\PycharmProjects\AutoTest_platform\lib\site-packages\sqlalchemy\engine\base.py", line 1521, in _execute_20
    return meth(self, args_10style, kwargs_10style, execution_options)
  File "D:\PycharmProjects\AutoTest_platform\lib\site-packages\sqlalchemy\sql\elements.py", line 314, in _execute_on_connection
    self, multiparams, params, execution_options
  File "D:\PycharmProjects\AutoTest_platform\lib\site-packages\sqlalchemy\engine\base.py", line 1400, in _execute_clauseelement
    cache_hit=cache_hit,
  File "D:\PycharmProjects\AutoTest_platform\lib\site-packages\sqlalchemy\engine\base.py", line 1750, in _execute_context
    e, statement, parameters, cursor, context
  File "D:\PycharmProjects\AutoTest_platform\lib\site-packages\sqlalchemy\engine\base.py", line 1931, in _handle_dbapi_exception
    sqlalchemy_exception, with_traceback=exc_info[2], from_=e
  File "D:\PycharmProjects\AutoTest_platform\lib\site-packages\sqlalchemy\util\compat.py", line 211, in raise_
    raise exception
  File "D:\PycharmProjects\AutoTest_platform\lib\site-packages\sqlalchemy\engine\base.py", line 1707, in _execute_context
    cursor, statement, parameters, context
  File "D:\PycharmProjects\AutoTest_platform\lib\site-packages\sqlalchemy\engine\default.py", line 716, in do_execute
    cursor.execute(statement, parameters)
  File "D:\PycharmProjects\AutoTest_platform\lib\site-packages\pymysql\cursors.py", line 148, in execute
    result = self._query(query)
  File "D:\PycharmProjects\AutoTest_platform\lib\site-packages\pymysql\cursors.py", line 310, in _query
    conn.query(q)
  File "D:\PycharmProjects\AutoTest_platform\lib\site-packages\pymysql\connections.py", line 548, in query
    self._affected_rows = self._read_query_result(unbuffered=unbuffered)
  File "D:\PycharmProjects\AutoTest_platform\lib\site-packages\pymysql\connections.py", line 775, in _read_query_result
    result.read()
  File "D:\PycharmProjects\AutoTest_platform\lib\site-packages\pymysql\connections.py", line 1156, in read
    first_packet = self.connection._read_packet()
  File "D:\PycharmProjects\AutoTest_platform\lib\site-packages\pymysql\connections.py", line 725, in _read_packet
    packet.raise_for_error()
  File "D:\PycharmProjects\AutoTest_platform\lib\site-packages\pymysql\protocol.py", line 221, in raise_for_error
    err.raise_mysql_exception(self._data)
  File "D:\PycharmProjects\AutoTest_platform\lib\site-packages\pymysql\err.py", line 143, in raise_mysql_exception
    raise errorclass(errno, errval)
sqlalchemy.exc.OperationalError: (pymysql.err.OperationalError) (1241, 'Operand should contain 1 column(s)')
[SQL: UPDATE submitted_tests SET submitted_date=%(submitted_date)s, test_date=%(test_date)s, fix_bug_director_id=%(fix_bug_director_id)s WHERE submitted_tests.id = %(submitted_tests_id)s]
[parameters: {'submitted_date': datetime.datetime(2022, 6, 2, 0, 0), 'test_date': datetime.datetime(2022, 6, 2, 0, 0), 'fix_bug_director_id': [4, 5], 'submitted_tests_id': 31}]
(Background on this error at: http://sqlalche.me/e/14/e3q8)

[2022-06-29 17:39:26,558] [log.py|__console] [line:43] ERROR   : Traceback (most recent call last):
  File "D:\PycharmProjects\AutoTest_platform\lib\site-packages\sqlalchemy\engine\base.py", line 1707, in _execute_context
    cursor, statement, parameters, context
  File "D:\PycharmProjects\AutoTest_platform\lib\site-packages\sqlalchemy\engine\default.py", line 716, in do_execute
    cursor.execute(statement, parameters)
  File "D:\PycharmProjects\AutoTest_platform\lib\site-packages\pymysql\cursors.py", line 148, in execute
    result = self._query(query)
  File "D:\PycharmProjects\AutoTest_platform\lib\site-packages\pymysql\cursors.py", line 310, in _query
    conn.query(q)
  File "D:\PycharmProjects\AutoTest_platform\lib\site-packages\pymysql\connections.py", line 548, in query
    self._affected_rows = self._read_query_result(unbuffered=unbuffered)
  File "D:\PycharmProjects\AutoTest_platform\lib\site-packages\pymysql\connections.py", line 775, in _read_query_result
    result.read()
  File "D:\PycharmProjects\AutoTest_platform\lib\site-packages\pymysql\connections.py", line 1156, in read
    first_packet = self.connection._read_packet()
  File "D:\PycharmProjects\AutoTest_platform\lib\site-packages\pymysql\connections.py", line 725, in _read_packet
    packet.raise_for_error()
  File "D:\PycharmProjects\AutoTest_platform\lib\site-packages\pymysql\protocol.py", line 221, in raise_for_error
    err.raise_mysql_exception(self._data)
  File "D:\PycharmProjects\AutoTest_platform\lib\site-packages\pymysql\err.py", line 143, in raise_mysql_exception
    raise errorclass(errno, errval)
pymysql.err.IntegrityError: (1451, 'Cannot delete or update a parent row: a foreign key constraint fails (`autotest_platform_prod`.`user_project`, CONSTRAINT `user_project_ibfk_1` FOREIGN KEY (`user_id`) REFERENCES `user` (`id`))')

The above exception was the direct cause of the following exception:

Traceback (most recent call last):
  File "D:\PycharmProjects\AutoTest_platform\lib\site-packages\flask\app.py", line 1950, in full_dispatch_request
    rv = self.dispatch_request()
  File "D:\PycharmProjects\AutoTest_platform\lib\site-packages\flask\app.py", line 1936, in dispatch_request
    return self.view_functions[rule.endpoint](**req.view_args)
  File "D:\PycharmProjects\AutoTest_platform\utils\tokenUtil.py", line 64, in wrapper
    return func(*args, **kw)
  File "D:\PycharmProjects\AutoTest_platform\views\base\userView.py", line 197, in delete_user
    db.session.commit()
  File "<string>", line 2, in commit
  File "D:\PycharmProjects\AutoTest_platform\lib\site-packages\sqlalchemy\orm\session.py", line 1423, in commit
    self._transaction.commit(_to_root=self.future)
  File "D:\PycharmProjects\AutoTest_platform\lib\site-packages\sqlalchemy\orm\session.py", line 829, in commit
    self._prepare_impl()
  File "D:\PycharmProjects\AutoTest_platform\lib\site-packages\sqlalchemy\orm\session.py", line 808, in _prepare_impl
    self.session.flush()
  File "D:\PycharmProjects\AutoTest_platform\lib\site-packages\sqlalchemy\orm\session.py", line 3255, in flush
    self._flush(objects)
  File "D:\PycharmProjects\AutoTest_platform\lib\site-packages\sqlalchemy\orm\session.py", line 3395, in _flush
    transaction.rollback(_capture_exception=True)
  File "D:\PycharmProjects\AutoTest_platform\lib\site-packages\sqlalchemy\util\langhelpers.py", line 72, in __exit__
    with_traceback=exc_tb,
  File "D:\PycharmProjects\AutoTest_platform\lib\site-packages\sqlalchemy\util\compat.py", line 211, in raise_
    raise exception
  File "D:\PycharmProjects\AutoTest_platform\lib\site-packages\sqlalchemy\orm\session.py", line 3355, in _flush
    flush_context.execute()
  File "D:\PycharmProjects\AutoTest_platform\lib\site-packages\sqlalchemy\orm\unitofwork.py", line 453, in execute
    rec.execute(self)
  File "D:\PycharmProjects\AutoTest_platform\lib\site-packages\sqlalchemy\orm\unitofwork.py", line 667, in execute
    uow,
  File "D:\PycharmProjects\AutoTest_platform\lib\site-packages\sqlalchemy\orm\persistence.py", line 345, in delete_obj
    delete,
  File "D:\PycharmProjects\AutoTest_platform\lib\site-packages\sqlalchemy\orm\persistence.py", line 1441, in _emit_delete_statements
    statement, del_objects, execution_options=execution_options
  File "D:\PycharmProjects\AutoTest_platform\lib\site-packages\sqlalchemy\engine\base.py", line 1521, in _execute_20
    return meth(self, args_10style, kwargs_10style, execution_options)
  File "D:\PycharmProjects\AutoTest_platform\lib\site-packages\sqlalchemy\sql\elements.py", line 314, in _execute_on_connection
    self, multiparams, params, execution_options
  File "D:\PycharmProjects\AutoTest_platform\lib\site-packages\sqlalchemy\engine\base.py", line 1400, in _execute_clauseelement
    cache_hit=cache_hit,
  File "D:\PycharmProjects\AutoTest_platform\lib\site-packages\sqlalchemy\engine\base.py", line 1750, in _execute_context
    e, statement, parameters, cursor, context
  File "D:\PycharmProjects\AutoTest_platform\lib\site-packages\sqlalchemy\engine\base.py", line 1931, in _handle_dbapi_exception
    sqlalchemy_exception, with_traceback=exc_info[2], from_=e
  File "D:\PycharmProjects\AutoTest_platform\lib\site-packages\sqlalchemy\util\compat.py", line 211, in raise_
    raise exception
  File "D:\PycharmProjects\AutoTest_platform\lib\site-packages\sqlalchemy\engine\base.py", line 1707, in _execute_context
    cursor, statement, parameters, context
  File "D:\PycharmProjects\AutoTest_platform\lib\site-packages\sqlalchemy\engine\default.py", line 716, in do_execute
    cursor.execute(statement, parameters)
  File "D:\PycharmProjects\AutoTest_platform\lib\site-packages\pymysql\cursors.py", line 148, in execute
    result = self._query(query)
  File "D:\PycharmProjects\AutoTest_platform\lib\site-packages\pymysql\cursors.py", line 310, in _query
    conn.query(q)
  File "D:\PycharmProjects\AutoTest_platform\lib\site-packages\pymysql\connections.py", line 548, in query
    self._affected_rows = self._read_query_result(unbuffered=unbuffered)
  File "D:\PycharmProjects\AutoTest_platform\lib\site-packages\pymysql\connections.py", line 775, in _read_query_result
    result.read()
  File "D:\PycharmProjects\AutoTest_platform\lib\site-packages\pymysql\connections.py", line 1156, in read
    first_packet = self.connection._read_packet()
  File "D:\PycharmProjects\AutoTest_platform\lib\site-packages\pymysql\connections.py", line 725, in _read_packet
    packet.raise_for_error()
  File "D:\PycharmProjects\AutoTest_platform\lib\site-packages\pymysql\protocol.py", line 221, in raise_for_error
    err.raise_mysql_exception(self._data)
  File "D:\PycharmProjects\AutoTest_platform\lib\site-packages\pymysql\err.py", line 143, in raise_mysql_exception
    raise errorclass(errno, errval)
sqlalchemy.exc.IntegrityError: (pymysql.err.IntegrityError) (1451, 'Cannot delete or update a parent row: a foreign key constraint fails (`autotest_platform_prod`.`user_project`, CONSTRAINT `user_project_ibfk_1` FOREIGN KEY (`user_id`) REFERENCES `user` (`id`))')
[SQL: DELETE FROM user WHERE user.id = %(id)s]
[parameters: {'id': 5}]
(Background on this error at: http://sqlalche.me/e/14/gkpj)

[2022-06-29 17:39:31,931] [log.py|__console] [line:43] ERROR   : Traceback (most recent call last):
  File "D:\PycharmProjects\AutoTest_platform\lib\site-packages\sqlalchemy\engine\base.py", line 1707, in _execute_context
    cursor, statement, parameters, context
  File "D:\PycharmProjects\AutoTest_platform\lib\site-packages\sqlalchemy\engine\default.py", line 716, in do_execute
    cursor.execute(statement, parameters)
  File "D:\PycharmProjects\AutoTest_platform\lib\site-packages\pymysql\cursors.py", line 148, in execute
    result = self._query(query)
  File "D:\PycharmProjects\AutoTest_platform\lib\site-packages\pymysql\cursors.py", line 310, in _query
    conn.query(q)
  File "D:\PycharmProjects\AutoTest_platform\lib\site-packages\pymysql\connections.py", line 548, in query
    self._affected_rows = self._read_query_result(unbuffered=unbuffered)
  File "D:\PycharmProjects\AutoTest_platform\lib\site-packages\pymysql\connections.py", line 775, in _read_query_result
    result.read()
  File "D:\PycharmProjects\AutoTest_platform\lib\site-packages\pymysql\connections.py", line 1156, in read
    first_packet = self.connection._read_packet()
  File "D:\PycharmProjects\AutoTest_platform\lib\site-packages\pymysql\connections.py", line 725, in _read_packet
    packet.raise_for_error()
  File "D:\PycharmProjects\AutoTest_platform\lib\site-packages\pymysql\protocol.py", line 221, in raise_for_error
    err.raise_mysql_exception(self._data)
  File "D:\PycharmProjects\AutoTest_platform\lib\site-packages\pymysql\err.py", line 143, in raise_mysql_exception
    raise errorclass(errno, errval)
pymysql.err.IntegrityError: (1451, 'Cannot delete or update a parent row: a foreign key constraint fails (`autotest_platform_prod`.`user_project`, CONSTRAINT `user_project_ibfk_1` FOREIGN KEY (`user_id`) REFERENCES `user` (`id`))')

The above exception was the direct cause of the following exception:

Traceback (most recent call last):
  File "D:\PycharmProjects\AutoTest_platform\lib\site-packages\flask\app.py", line 1950, in full_dispatch_request
    rv = self.dispatch_request()
  File "D:\PycharmProjects\AutoTest_platform\lib\site-packages\flask\app.py", line 1936, in dispatch_request
    return self.view_functions[rule.endpoint](**req.view_args)
  File "D:\PycharmProjects\AutoTest_platform\utils\tokenUtil.py", line 64, in wrapper
    return func(*args, **kw)
  File "D:\PycharmProjects\AutoTest_platform\views\base\userView.py", line 197, in delete_user
    db.session.commit()
  File "<string>", line 2, in commit
  File "D:\PycharmProjects\AutoTest_platform\lib\site-packages\sqlalchemy\orm\session.py", line 1423, in commit
    self._transaction.commit(_to_root=self.future)
  File "D:\PycharmProjects\AutoTest_platform\lib\site-packages\sqlalchemy\orm\session.py", line 829, in commit
    self._prepare_impl()
  File "D:\PycharmProjects\AutoTest_platform\lib\site-packages\sqlalchemy\orm\session.py", line 808, in _prepare_impl
    self.session.flush()
  File "D:\PycharmProjects\AutoTest_platform\lib\site-packages\sqlalchemy\orm\session.py", line 3255, in flush
    self._flush(objects)
  File "D:\PycharmProjects\AutoTest_platform\lib\site-packages\sqlalchemy\orm\session.py", line 3395, in _flush
    transaction.rollback(_capture_exception=True)
  File "D:\PycharmProjects\AutoTest_platform\lib\site-packages\sqlalchemy\util\langhelpers.py", line 72, in __exit__
    with_traceback=exc_tb,
  File "D:\PycharmProjects\AutoTest_platform\lib\site-packages\sqlalchemy\util\compat.py", line 211, in raise_
    raise exception
  File "D:\PycharmProjects\AutoTest_platform\lib\site-packages\sqlalchemy\orm\session.py", line 3355, in _flush
    flush_context.execute()
  File "D:\PycharmProjects\AutoTest_platform\lib\site-packages\sqlalchemy\orm\unitofwork.py", line 453, in execute
    rec.execute(self)
  File "D:\PycharmProjects\AutoTest_platform\lib\site-packages\sqlalchemy\orm\unitofwork.py", line 667, in execute
    uow,
  File "D:\PycharmProjects\AutoTest_platform\lib\site-packages\sqlalchemy\orm\persistence.py", line 345, in delete_obj
    delete,
  File "D:\PycharmProjects\AutoTest_platform\lib\site-packages\sqlalchemy\orm\persistence.py", line 1441, in _emit_delete_statements
    statement, del_objects, execution_options=execution_options
  File "D:\PycharmProjects\AutoTest_platform\lib\site-packages\sqlalchemy\engine\base.py", line 1521, in _execute_20
    return meth(self, args_10style, kwargs_10style, execution_options)
  File "D:\PycharmProjects\AutoTest_platform\lib\site-packages\sqlalchemy\sql\elements.py", line 314, in _execute_on_connection
    self, multiparams, params, execution_options
  File "D:\PycharmProjects\AutoTest_platform\lib\site-packages\sqlalchemy\engine\base.py", line 1400, in _execute_clauseelement
    cache_hit=cache_hit,
  File "D:\PycharmProjects\AutoTest_platform\lib\site-packages\sqlalchemy\engine\base.py", line 1750, in _execute_context
    e, statement, parameters, cursor, context
  File "D:\PycharmProjects\AutoTest_platform\lib\site-packages\sqlalchemy\engine\base.py", line 1931, in _handle_dbapi_exception
    sqlalchemy_exception, with_traceback=exc_info[2], from_=e
  File "D:\PycharmProjects\AutoTest_platform\lib\site-packages\sqlalchemy\util\compat.py", line 211, in raise_
    raise exception
  File "D:\PycharmProjects\AutoTest_platform\lib\site-packages\sqlalchemy\engine\base.py", line 1707, in _execute_context
    cursor, statement, parameters, context
  File "D:\PycharmProjects\AutoTest_platform\lib\site-packages\sqlalchemy\engine\default.py", line 716, in do_execute
    cursor.execute(statement, parameters)
  File "D:\PycharmProjects\AutoTest_platform\lib\site-packages\pymysql\cursors.py", line 148, in execute
    result = self._query(query)
  File "D:\PycharmProjects\AutoTest_platform\lib\site-packages\pymysql\cursors.py", line 310, in _query
    conn.query(q)
  File "D:\PycharmProjects\AutoTest_platform\lib\site-packages\pymysql\connections.py", line 548, in query
    self._affected_rows = self._read_query_result(unbuffered=unbuffered)
  File "D:\PycharmProjects\AutoTest_platform\lib\site-packages\pymysql\connections.py", line 775, in _read_query_result
    result.read()
  File "D:\PycharmProjects\AutoTest_platform\lib\site-packages\pymysql\connections.py", line 1156, in read
    first_packet = self.connection._read_packet()
  File "D:\PycharmProjects\AutoTest_platform\lib\site-packages\pymysql\connections.py", line 725, in _read_packet
    packet.raise_for_error()
  File "D:\PycharmProjects\AutoTest_platform\lib\site-packages\pymysql\protocol.py", line 221, in raise_for_error
    err.raise_mysql_exception(self._data)
  File "D:\PycharmProjects\AutoTest_platform\lib\site-packages\pymysql\err.py", line 143, in raise_mysql_exception
    raise errorclass(errno, errval)
sqlalchemy.exc.IntegrityError: (pymysql.err.IntegrityError) (1451, 'Cannot delete or update a parent row: a foreign key constraint fails (`autotest_platform_prod`.`user_project`, CONSTRAINT `user_project_ibfk_1` FOREIGN KEY (`user_id`) REFERENCES `user` (`id`))')
[SQL: DELETE FROM user WHERE user.id = %(id)s]
[parameters: {'id': 5}]
(Background on this error at: http://sqlalche.me/e/14/gkpj)

[2022-06-29 17:39:36,295] [log.py|__console] [line:43] ERROR   : Traceback (most recent call last):
  File "D:\PycharmProjects\AutoTest_platform\lib\site-packages\sqlalchemy\engine\base.py", line 1707, in _execute_context
    cursor, statement, parameters, context
  File "D:\PycharmProjects\AutoTest_platform\lib\site-packages\sqlalchemy\engine\default.py", line 716, in do_execute
    cursor.execute(statement, parameters)
  File "D:\PycharmProjects\AutoTest_platform\lib\site-packages\pymysql\cursors.py", line 148, in execute
    result = self._query(query)
  File "D:\PycharmProjects\AutoTest_platform\lib\site-packages\pymysql\cursors.py", line 310, in _query
    conn.query(q)
  File "D:\PycharmProjects\AutoTest_platform\lib\site-packages\pymysql\connections.py", line 548, in query
    self._affected_rows = self._read_query_result(unbuffered=unbuffered)
  File "D:\PycharmProjects\AutoTest_platform\lib\site-packages\pymysql\connections.py", line 775, in _read_query_result
    result.read()
  File "D:\PycharmProjects\AutoTest_platform\lib\site-packages\pymysql\connections.py", line 1156, in read
    first_packet = self.connection._read_packet()
  File "D:\PycharmProjects\AutoTest_platform\lib\site-packages\pymysql\connections.py", line 725, in _read_packet
    packet.raise_for_error()
  File "D:\PycharmProjects\AutoTest_platform\lib\site-packages\pymysql\protocol.py", line 221, in raise_for_error
    err.raise_mysql_exception(self._data)
  File "D:\PycharmProjects\AutoTest_platform\lib\site-packages\pymysql\err.py", line 143, in raise_mysql_exception
    raise errorclass(errno, errval)
pymysql.err.IntegrityError: (1451, 'Cannot delete or update a parent row: a foreign key constraint fails (`autotest_platform_prod`.`user_project`, CONSTRAINT `user_project_ibfk_1` FOREIGN KEY (`user_id`) REFERENCES `user` (`id`))')

The above exception was the direct cause of the following exception:

Traceback (most recent call last):
  File "D:\PycharmProjects\AutoTest_platform\lib\site-packages\flask\app.py", line 1950, in full_dispatch_request
    rv = self.dispatch_request()
  File "D:\PycharmProjects\AutoTest_platform\lib\site-packages\flask\app.py", line 1936, in dispatch_request
    return self.view_functions[rule.endpoint](**req.view_args)
  File "D:\PycharmProjects\AutoTest_platform\utils\tokenUtil.py", line 64, in wrapper
    return func(*args, **kw)
  File "D:\PycharmProjects\AutoTest_platform\views\base\userView.py", line 197, in delete_user
    db.session.commit()
  File "<string>", line 2, in commit
  File "D:\PycharmProjects\AutoTest_platform\lib\site-packages\sqlalchemy\orm\session.py", line 1423, in commit
    self._transaction.commit(_to_root=self.future)
  File "D:\PycharmProjects\AutoTest_platform\lib\site-packages\sqlalchemy\orm\session.py", line 829, in commit
    self._prepare_impl()
  File "D:\PycharmProjects\AutoTest_platform\lib\site-packages\sqlalchemy\orm\session.py", line 808, in _prepare_impl
    self.session.flush()
  File "D:\PycharmProjects\AutoTest_platform\lib\site-packages\sqlalchemy\orm\session.py", line 3255, in flush
    self._flush(objects)
  File "D:\PycharmProjects\AutoTest_platform\lib\site-packages\sqlalchemy\orm\session.py", line 3395, in _flush
    transaction.rollback(_capture_exception=True)
  File "D:\PycharmProjects\AutoTest_platform\lib\site-packages\sqlalchemy\util\langhelpers.py", line 72, in __exit__
    with_traceback=exc_tb,
  File "D:\PycharmProjects\AutoTest_platform\lib\site-packages\sqlalchemy\util\compat.py", line 211, in raise_
    raise exception
  File "D:\PycharmProjects\AutoTest_platform\lib\site-packages\sqlalchemy\orm\session.py", line 3355, in _flush
    flush_context.execute()
  File "D:\PycharmProjects\AutoTest_platform\lib\site-packages\sqlalchemy\orm\unitofwork.py", line 453, in execute
    rec.execute(self)
  File "D:\PycharmProjects\AutoTest_platform\lib\site-packages\sqlalchemy\orm\unitofwork.py", line 667, in execute
    uow,
  File "D:\PycharmProjects\AutoTest_platform\lib\site-packages\sqlalchemy\orm\persistence.py", line 345, in delete_obj
    delete,
  File "D:\PycharmProjects\AutoTest_platform\lib\site-packages\sqlalchemy\orm\persistence.py", line 1441, in _emit_delete_statements
    statement, del_objects, execution_options=execution_options
  File "D:\PycharmProjects\AutoTest_platform\lib\site-packages\sqlalchemy\engine\base.py", line 1521, in _execute_20
    return meth(self, args_10style, kwargs_10style, execution_options)
  File "D:\PycharmProjects\AutoTest_platform\lib\site-packages\sqlalchemy\sql\elements.py", line 314, in _execute_on_connection
    self, multiparams, params, execution_options
  File "D:\PycharmProjects\AutoTest_platform\lib\site-packages\sqlalchemy\engine\base.py", line 1400, in _execute_clauseelement
    cache_hit=cache_hit,
  File "D:\PycharmProjects\AutoTest_platform\lib\site-packages\sqlalchemy\engine\base.py", line 1750, in _execute_context
    e, statement, parameters, cursor, context
  File "D:\PycharmProjects\AutoTest_platform\lib\site-packages\sqlalchemy\engine\base.py", line 1931, in _handle_dbapi_exception
    sqlalchemy_exception, with_traceback=exc_info[2], from_=e
  File "D:\PycharmProjects\AutoTest_platform\lib\site-packages\sqlalchemy\util\compat.py", line 211, in raise_
    raise exception
  File "D:\PycharmProjects\AutoTest_platform\lib\site-packages\sqlalchemy\engine\base.py", line 1707, in _execute_context
    cursor, statement, parameters, context
  File "D:\PycharmProjects\AutoTest_platform\lib\site-packages\sqlalchemy\engine\default.py", line 716, in do_execute
    cursor.execute(statement, parameters)
  File "D:\PycharmProjects\AutoTest_platform\lib\site-packages\pymysql\cursors.py", line 148, in execute
    result = self._query(query)
  File "D:\PycharmProjects\AutoTest_platform\lib\site-packages\pymysql\cursors.py", line 310, in _query
    conn.query(q)
  File "D:\PycharmProjects\AutoTest_platform\lib\site-packages\pymysql\connections.py", line 548, in query
    self._affected_rows = self._read_query_result(unbuffered=unbuffered)
  File "D:\PycharmProjects\AutoTest_platform\lib\site-packages\pymysql\connections.py", line 775, in _read_query_result
    result.read()
  File "D:\PycharmProjects\AutoTest_platform\lib\site-packages\pymysql\connections.py", line 1156, in read
    first_packet = self.connection._read_packet()
  File "D:\PycharmProjects\AutoTest_platform\lib\site-packages\pymysql\connections.py", line 725, in _read_packet
    packet.raise_for_error()
  File "D:\PycharmProjects\AutoTest_platform\lib\site-packages\pymysql\protocol.py", line 221, in raise_for_error
    err.raise_mysql_exception(self._data)
  File "D:\PycharmProjects\AutoTest_platform\lib\site-packages\pymysql\err.py", line 143, in raise_mysql_exception
    raise errorclass(errno, errval)
sqlalchemy.exc.IntegrityError: (pymysql.err.IntegrityError) (1451, 'Cannot delete or update a parent row: a foreign key constraint fails (`autotest_platform_prod`.`user_project`, CONSTRAINT `user_project_ibfk_1` FOREIGN KEY (`user_id`) REFERENCES `user` (`id`))')
[SQL: DELETE FROM user WHERE user.id = %(id)s]
[parameters: {'id': 5}]
(Background on this error at: http://sqlalche.me/e/14/gkpj)

